[2022-10-04T12:51:21.191+0000] {taskinstance.py:1165} INFO - Dependencies all met for <TaskInstance: dag_with_postgres_hooks_v2.postgres_to_s3 scheduled__2022-10-02T00:00:00+00:00 [queued]>
[2022-10-04T12:51:21.224+0000] {taskinstance.py:1165} INFO - Dependencies all met for <TaskInstance: dag_with_postgres_hooks_v2.postgres_to_s3 scheduled__2022-10-02T00:00:00+00:00 [queued]>
[2022-10-04T12:51:21.225+0000] {taskinstance.py:1362} INFO - 
--------------------------------------------------------------------------------
[2022-10-04T12:51:21.225+0000] {taskinstance.py:1363} INFO - Starting attempt 2 of 3
[2022-10-04T12:51:21.226+0000] {taskinstance.py:1364} INFO - 
--------------------------------------------------------------------------------
[2022-10-04T12:51:21.275+0000] {taskinstance.py:1383} INFO - Executing <Task(PythonOperator): postgres_to_s3> on 2022-10-02 00:00:00+00:00
[2022-10-04T12:51:21.285+0000] {standard_task_runner.py:54} INFO - Started process 19135 to run task
[2022-10-04T12:51:21.293+0000] {standard_task_runner.py:82} INFO - Running: ['***', 'tasks', 'run', 'dag_with_postgres_hooks_v2', 'postgres_to_s3', 'scheduled__2022-10-02T00:00:00+00:00', '--job-id', '124', '--raw', '--subdir', 'DAGS_FOLDER/dag_with_postgres_hooks.py', '--cfg-path', '/tmp/tmpzt468434']
[2022-10-04T12:51:21.296+0000] {standard_task_runner.py:83} INFO - Job 124: Subtask postgres_to_s3
[2022-10-04T12:51:21.298+0000] {dagbag.py:525} INFO - Filling up the DagBag from /opt/***/dags/dag_with_postgres_hooks.py
[2022-10-04T12:51:22.072+0000] {task_command.py:384} INFO - Running <TaskInstance: dag_with_postgres_hooks_v2.postgres_to_s3 scheduled__2022-10-02T00:00:00+00:00 [running]> on host fe59f3828ca7
[2022-10-04T12:51:22.308+0000] {taskinstance.py:1592} INFO - Exporting the following env vars:
AIRFLOW_CTX_DAG_OWNER=***
AIRFLOW_CTX_DAG_ID=dag_with_postgres_hooks_v2
AIRFLOW_CTX_TASK_ID=postgres_to_s3
AIRFLOW_CTX_EXECUTION_DATE=2022-10-02T00:00:00+00:00
AIRFLOW_CTX_TRY_NUMBER=2
AIRFLOW_CTX_DAG_RUN_ID=scheduled__2022-10-02T00:00:00+00:00
[2022-10-04T12:51:22.326+0000] {logging_mixin.py:117} WARNING - /home/***/.local/lib/python3.7/site-packages/***/utils/context.py:204 AirflowContextDeprecationWarning: Accessing 'next_ds_nodash' from the template is deprecated and will be removed in a future version. Please use '{{ data_interval_end | ds_nodash }}' instead.
[2022-10-04T12:51:22.352+0000] {base.py:71} INFO - Using connection ID 'postgres_localhost' for task execution.
[2022-10-04T12:51:22.395+0000] {dag_with_postgres_hooks.py:33} INFO - saved orders data to file : dags/get_orders_20221002.txt
[2022-10-04T12:51:22.417+0000] {base.py:71} INFO - Using connection ID 'minio_conn' for task execution.
[2022-10-04T12:51:22.421+0000] {connection_wrapper.py:303} INFO - AWS Connection (conn_id='minio_conn', conn_type='aws') credentials retrieved from login and password.
[2022-10-04T12:51:22.426+0000] {logging_mixin.py:117} WARNING - /home/***/.local/lib/python3.7/site-packages/***/providers/amazon/aws/utils/connection_wrapper.py:8 DeprecationWarning: extra['host'] is deprecated and will be removed in a future release. Please set extra['endpoint_url'] instead
[2022-10-04T12:51:22.661+0000] {taskinstance.py:1851} ERROR - Task failed with exception
Traceback (most recent call last):
  File "/home/airflow/.local/lib/python3.7/site-packages/boto3/s3/transfer.py", line 288, in upload_file
    future.result()
  File "/home/airflow/.local/lib/python3.7/site-packages/s3transfer/futures.py", line 103, in result
    return self._coordinator.result()
  File "/home/airflow/.local/lib/python3.7/site-packages/s3transfer/futures.py", line 266, in result
    raise self._exception
  File "/home/airflow/.local/lib/python3.7/site-packages/s3transfer/tasks.py", line 139, in __call__
    return self._execute_main(kwargs)
  File "/home/airflow/.local/lib/python3.7/site-packages/s3transfer/tasks.py", line 162, in _execute_main
    return_value = self._main(**kwargs)
  File "/home/airflow/.local/lib/python3.7/site-packages/s3transfer/upload.py", line 758, in _main
    client.put_object(Bucket=bucket, Key=key, Body=body, **extra_args)
  File "/home/airflow/.local/lib/python3.7/site-packages/botocore/client.py", line 514, in _api_call
    return self._make_api_call(operation_name, kwargs)
  File "/home/airflow/.local/lib/python3.7/site-packages/botocore/client.py", line 938, in _make_api_call
    raise error_class(parsed_response, operation_name)
botocore.exceptions.ClientError: An error occurred (InvalidArgument) when calling the PutObject operation: S3 API Requests must be made to API port.

During handling of the above exception, another exception occurred:

Traceback (most recent call last):
  File "/home/airflow/.local/lib/python3.7/site-packages/airflow/operators/python.py", line 175, in execute
    return_value = self.execute_callable()
  File "/home/airflow/.local/lib/python3.7/site-packages/airflow/operators/python.py", line 193, in execute_callable
    return self.python_callable(*self.op_args, **self.op_kwargs)
  File "/opt/airflow/dags/dag_with_postgres_hooks.py", line 41, in postgres_to_s3
    replace=True
  File "/home/airflow/.local/lib/python3.7/site-packages/airflow/providers/amazon/aws/hooks/s3.py", line 64, in wrapper
    return func(*bound_args.args, **bound_args.kwargs)
  File "/home/airflow/.local/lib/python3.7/site-packages/airflow/providers/amazon/aws/hooks/s3.py", line 92, in wrapper
    return func(*bound_args.args, **bound_args.kwargs)
  File "/home/airflow/.local/lib/python3.7/site-packages/airflow/providers/amazon/aws/hooks/s3.py", line 649, in load_file
    client.upload_file(filename, bucket_name, key, ExtraArgs=extra_args, Config=self.transfer_config)
  File "/home/airflow/.local/lib/python3.7/site-packages/boto3/s3/inject.py", line 148, in upload_file
    callback=Callback,
  File "/home/airflow/.local/lib/python3.7/site-packages/boto3/s3/transfer.py", line 296, in upload_file
    filename, '/'.join([bucket, key]), e
boto3.exceptions.S3UploadFailedError: Failed to upload dags/get_orders_20221002.txt to ***/orders_20221002.txt: An error occurred (InvalidArgument) when calling the PutObject operation: S3 API Requests must be made to API port.
[2022-10-04T12:51:22.690+0000] {taskinstance.py:1406} INFO - Marking task as UP_FOR_RETRY. dag_id=dag_with_postgres_hooks_v2, task_id=postgres_to_s3, execution_date=20221002T000000, start_date=20221004T125121, end_date=20221004T125122
[2022-10-04T12:51:22.725+0000] {standard_task_runner.py:107} ERROR - Failed to execute job 124 for task postgres_to_s3 (Failed to upload dags/get_orders_20221002.txt to ***/orders_20221002.txt: An error occurred (InvalidArgument) when calling the PutObject operation: S3 API Requests must be made to API port.; 19135)
[2022-10-04T12:51:22.751+0000] {local_task_job.py:164} INFO - Task exited with return code 1
[2022-10-04T12:51:22.804+0000] {local_task_job.py:273} INFO - 0 downstream tasks scheduled from follow-on schedule check
